Workbook

Sheet Assumptions and Summary
B1: Renting Case | G1: Owning Case | Q1: Comparison
A2: To edit with your own numbers: with a Google Docs account, go to File -> make a copy
C4: Renting Assumptions | G4: House and Mortgage Assumptions | L4: Rates as a percent of the house value
A5: =HYPERLINK("http://www.holypotato.net/?p=1073","Or, download to excel with File -> Download as (or directly from the about page -- click here)") -> Or, download to excel with File -> Download as (or directly from the about page -- click here) | C5: Initial monthly rent: | D5: 4700 | G5: House purchase Price | H5: 1350000 | K5: Mortgage Interest rate: | L5: Maintenance % | M5: Property tax % | N5: Insurance % | O5: House Appreciation | Q5: After x years | R5: Winner
A6: Then in your copy, change the assumptions and figures to suit your situation | G6: Downpayment (needs % sign) | H6: 0.0833 | J6: First 5 Years | K6: 0.042 | L6: 0.005 | M6: 0.005 | N6: 0.00226 | O6: 0.03 | Q6: One | R6: =IF((R22>0),concatenate("Renting by $",round(R22,0)),concatenate("Buying by $",-round(R22,0))) -> Renting by $79314
G7: Amortization (Max 30) | H7: 25 | J7: Next 5 Years: | K7: 0.048 | L7: 0.005 | M7: 0.005 | N7: 0.0024 | O7: 0.03 | Q7: Five | R7: =IF((R26>0),concatenate("Renting by $",round(R26,0)),concatenate("Buying by $",-round(R26,0))) -> Buying by $1729
A8: Input fields are in 12-pt font | G8: Ontario Land Transfer Tax | H8: =IF((H5>400000),(4475+((H5-400000)*0.02)),IF((H5>250000),(2225+((H5-250000)*0.015)),IF((H5>55000),(275+((H5-55000)*0.01)),(H5*0.005)))) -> 23475 | J8: =("Final "&(H7-10))&" Years" -> Final 15 Years | K8: 0.048 | L8: 0.005 | M8: 0.005 | N8: 0.0025 | O8: 0.03 | Q8: Ten | R8: =IF((R31>0),concatenate("Renting by $",round(R31,0)),concatenate("Buying by $",-round(R31,0))) -> Buying by $71356
A9: Conclusion in blue to the right. | C9: CPI rate (rent increase) | D9: Investment return | E9: Renters insurance (% of monthly rent) | G9: Toronto Land Transfer Tax | H9: =IF((H18="YES"),IF((H5>400000),(3725+((H5-400000)*0.02)),IF((H5>55000),(275+((H5-55000)*0.01)),(H5*0.005))),0) -> 0 | Q9: Fifteen | R9: =IF((R36>0),concatenate("Renting by $",round(R36,0)),concatenate("Buying by $",-round(R36,0))) -> Buying by $123539
A10: For more on the spreadsheet: | B10: First 5 Years | C10: 0.025 | D10: 0.08 | E10: 0.01 | G10: Title Insurance | H10: 250 | K10: Calculated Monthly payment | M10: Built-in assumptions: | Q10: Twenty | R10: =IF((R41>0),concatenate("Renting by $",round(R41,0)),concatenate("Buying by $",-round(R41,0))) -> Buying by $128062
A11: http://www.holypotato.net/?p=1073 | B11: Next 5 Years: | C11: 0.025 | D11: 0.08 | E11: 0.01 | G11: Legal Fees (including disbursments) | H11: 1500 | J11: First 5 Years | K11: ='Monthly Mortgage Calculation'!I13 -> 6853.91 | M11: CMHC premium is capitalized to mortgage | Q11: Tweny Five | R11: =IF((R46>0),concatenate("Renting by $",round(R46,0)),concatenate("Buying by $",-round(R46,0))) -> Buying by $34676
B12: =("Final "&(H7-10))&" Years" -> Final 15 Years | C12: 0.025 | D12: 0.08 | E12: 0.01 | G12: Home Inspection | H12: 400 | J12: Next 5 Years: | K12: ='Monthly Mortgage Calculation'!I14 -> 7207.7221 | M12: Other closing costs are paid as cash | Q12: Thirty | R12: =IF((R51>0),concatenate("Renting by $",round(R51,0)),concatenate("Buying by $",-round(R51,0))) -> Renting by $228978
A13: (Note: If you don't see the file | G13: CMHC insurance | H13: =IF((H7>25),(IF((H6>=(20/100)),0,IF((H6>=(15/100)),(1.95/100),IF((H6>=(10/100)),(2.2/100),IF((H6>=(5/100)),(2.95/100),(100/100)))))),IF((H6>=(20/100)),0,IF((H6>=(15/100)),(1.8/100),IF((H6>=(10/100)),(2.4/100),IF((H6>=(5/100)),(3.15/100),(100/100)))))) -> 0.0315 | J13: =("Final "&(H7-10))&" Years" -> Final 15 Years | K13: ='Monthly Mortgage Calculation'!I15 -> 7207.7221 | M13: Buyer is not a first time homebuyer
A14: menu, click "Go to spreadsheet view" at the top/bottom) | C14: Investment Tax Rate: | D14: 0.35 | G14: Total Cash to be used toward purchase | H14: =(((((H6*H5)+H8)+H9)+H10)+H11)+H12 -> 138080 | M14: House is in Ontario
A15: Updates from March 8, 2014: | C15: Or, enter 0 here and an after-tax rate of investment return above
A16: http://www.holypotato.net/?p=1235 | G16: Other Assumptions
A17: Also be sure to check out the Value of Simple: A Practical Guide to Taking the Complexity Out of Investing | G17: Commission (on sale only) | H17: 0.025
A18: http://ValueofSimple.ca | G18: House is in Toronto (416) | H18: No
Q19: Net worth comparison without selling home | R19: Assuming house is sold (with sales commission, but no mortgage penalty), and investment portfolio taxed
B20: Year | C20: Cost of Renting | D20: Surplus vs owning (annual) | E20: Investment portfolio | G20: Mortgage (P+I) | H20: Maintenance | I20: Property Tax | J20: Insurance | K20: Annual Cash Outlay | L20: Mortgage Balance (opening) | M20: Beginning of year House Value | N20: Beginning of year Owner's Equity | P20: Timing of comparison | Q20: Renter ahead by | R20: Renter ahead by
B21: 2023 | C21: =($D$5*12)*(1+$E$10) -> 56964 | D21: =K21-C21 -> 41833.92 | E21: =H14 -> 138080 | G21: =$K$11*12 -> 82246.92 | H21: =$M21*L$6 -> 6750 | I21: =$M21*M$6 -> 6750 | J21: =$M21*N$6 -> 3051 | K21: =((G21+H21)+I21)+J21 -> 98797.92 | L21: ='Monthly Mortgage Calculation'!H2 -> 1276527.7 | M21: =H5 -> 1350000 | N21: =M21-L21 -> 73472.333 | P21: At time of Purchase | Q21: =E21-N21 -> 64607.668 | R21: =(E21)-((M21-($H$17*M21))-L21) -> 98357.667
B22: =B21+1 -> 2024 | C22: =C21*(1+C$10) -> 58388.1 | D22: =K22-C22 -> 40906.35 | E22: =(E21)*(1+$D$10)+(1+$D$10/2)*D21 -> 192633.68 | G22: =$K$11*12 -> 82246.92 | H22: =$M22*L$6 -> 6952.5 | I22: =$M22*M$6 -> 6952.5 | J22: =$M22*N$6 -> 3142.53 | K22: =((G22+H22)+I22)+J22 -> 99294.45 | L22: ='Monthly Mortgage Calculation'!E13 -> 1246870 | M22: =M21*(1+O$6) -> 1390500 | N22: =M22-L22 -> 143630.01 | P22: After 1 year | Q22: =E22-N22 -> 49003.664 | R22: =(-(E22-E$21-sum(D$21:D21))*($D$14))+E22-((M22-($H$17*M22))-L22) -> 79314.249
B23: =B22+1 -> 2025 | C23: =C22*(1+C$10) -> 59847.802 | D23: =K23-C23 -> 39958.074 | E23: =(E22)*(1+$D$10)+(1+$D$10/2)*D22 -> 250586.98 | G23: =$K$11*12 -> 82246.92 | H23: =$M23*L$6 -> 7161.075 | I23: =$M23*M$6 -> 7161.075 | J23: =$M23*N$6 -> 3236.8059 | K23: =((G23+H23)+I23)+J23 -> 99805.876 | L23: ='Monthly Mortgage Calculation'!E25 -> 1215953.6 | M23: =M22*(1+O$6) -> 1432215 | N23: =M23-L23 -> 216261.4 | P23: After 2 years | Q23: =E23-N23 -> 34325.58 | R23: =(-(E23-E$21-sum(D$21:D22))*($D$14))+E23-((M23-($H$17*M23))-L23) -> 59712.609
B24: =B23+1 -> 2026 | C24: =C23*(1+C$10) -> 61343.998 | D24: =K24-C24 -> 38988.647 | E24: =(E23)*(1+$D$10)+(1+$D$10/2)*D23 -> 312190.33 | G24: =$K$11*12 -> 82246.92 | H24: =$M24*L$6 -> 7375.9073 | I24: =$M24*M$6 -> 7375.9073 | J24: =$M24*N$6 -> 3333.9101 | K24: =((G24+H24)+I24)+J24 -> 100332.64 | L24: ='Monthly Mortgage Calculation'!E37 -> 1183725.1 | M24: =M23*(1+O$6) -> 1475181.4 | N24: =M24-L24 -> 291456.35 | P24: After 3 years | Q24: =E24-N24 -> 20733.981 | R24: =(-(E24-E$21-sum(D$21:D23))*($D$14))+E24-((M24-($H$17*M24))-L24) -> 39619.322
B25: =B24+1 -> 2027 | C25: =C24*(1+C$10) -> 62877.598 | D25: =K25-C25 -> 37997.619 | E25: =(E24)*(1+$D$10)+(1+$D$10/2)*D24 -> 377713.75 | G25: =$K$11*12 -> 82246.92 | H25: =$M25*L$6 -> 7597.1845 | I25: =$M25*M$6 -> 7597.1845 | J25: =$M25*N$6 -> 3433.9274 | K25: =((G25+H25)+I25)+J25 -> 100875.22 | L25: ='Monthly Mortgage Calculation'!E49 -> 1150128.8 | M25: =M24*(1+O$6) -> 1519436.9 | N25: =M25-L25 -> 369308.11 | P25: After 4 Years | Q25: =E25-N25 -> 8405.6427 | R25: =(-(E25-E$21-sum(D$21:D24))*($D$14))+E25-((M25-($H$17*M25))-L25) -> 19110.2
B26: =B25+1 -> 2028 | C26: =((C25*(1+C$10)))*(1+E11)/(1+E10) -> 64449.537 | D26: =K26-C26 -> 41449.375 | E26: =(E25)*(1+$D$11)+(1+$D$11/2)*D25 -> 447448.37 | G26: =$K$12*12 -> 86492.665 | H26: =$M26*L$7 -> 7825.1 | I26: =$M26*M$7 -> 7825.1 | J26: =$M26*N$7 -> 3756.048 | K26: =((G26+H26)+I26)+J26 -> 105898.91 | L26: ='Monthly Mortgage Calculation'!E61 -> 1115106.6 | M26: =M25*(1+O$6) -> 1565020 | N26: =M26-L26 -> 449913.39 | P26: After 5 Years | Q26: =E26-N26 -> -2465.0157 | R26: =(-(E26-E$21-sum(D$21:D25))*($D$14))+E26-((M26-($H$17*M26))-L26) -> -1728.8327
B27: =B26+1 -> 2029 | C27: =C26*(1+C$11) -> 66060.776 | D27: =K27-C27 -> 40420.325 | E27: =(E26)*(1+$D$11)+(1+$D$11/2)*D26 -> 526351.59 | G27: =$K$12*12 -> 86492.665 | H27: =$M27*L$7 -> 8059.853 | I27: =$M27*M$7 -> 8059.853 | J27: =$M27*N$7 -> 3868.7294 | K27: =((G27+H27)+I27)+J27 -> 106481.1 | L27: ='Monthly Mortgage Calculation'!E73 -> 1080872.2 | M27: =M26*(1+O$7) -> 1611970.6 | N27: =M27-L27 -> 531098.42 | P27: After 6 Years | Q27: =E27-N27 -> -4746.8227 | R27: =(-(E27-E$21-sum(D$21:D26))*($D$14))+E27-((M27-($H$17*M27))-L27) -> -15945.721
B28: =B27+1 -> 2030 | C28: =C27*(1+C$11) -> 67712.295 | D28: =K28-C28 -> 39368.458 | E28: =(E27)*(1+$D$11)+(1+$D$11/2)*D27 -> 610496.86 | G28: =$K$12*12 -> 86492.665 | H28: =$M28*L$7 -> 8301.6486 | I28: =$M28*M$7 -> 8301.6486 | J28: =$M28*N$7 -> 3984.7913 | K28: =((G28+H28)+I28)+J28 -> 107080.75 | L28: ='Monthly Mortgage Calculation'!E85 -> 1044974.8 | M28: =M27*(1+O$7) -> 1660329.7 | N28: =M28-L28 -> 615354.93 | P28: After 7 Years | Q28: =E28-N28 -> -4858.0747 | R28: =(-(E28-E$21-sum(D$21:D27))*($D$14))+E28-((M28-($H$17*M28))-L28) -> -30151.724
B29: =B28+1 -> 2031 | C29: =C28*(1+C$11) -> 69405.103 | D29: =K29-C29 -> 38293.293 | E29: =(E28)*(1+$D$11)+(1+$D$11/2)*D28 -> 700279.8 | G29: =$K$12*12 -> 86492.665 | H29: =$M29*L$7 -> 8550.698 | I29: =$M29*M$7 -> 8550.698 | J29: =$M29*N$7 -> 4104.3351 | K29: =((G29+H29)+I29)+J29 -> 107698.4 | L29: ='Monthly Mortgage Calculation'!E97 -> 1007333.6 | M29: =M28*(1+O$7) -> 1710139.6 | N29: =M29-L29 -> 702805.98 | P29: After 8 Years | Q29: =E29-N29 -> -2526.1721 | R29: =(-(E29-E$21-sum(D$21:D28))*($D$14))+E29-((M29-($H$17*M29))-L29) -> -44219.644
B30: =B29+1 -> 2032 | C30: =C29*(1+C$11) -> 71140.23 | D30: =K30-C30 -> 37194.338 | E30: =(E29)*(1+$D$11)+(1+$D$11/2)*D29 -> 796127.21 | G30: =$K$12*12 -> 86492.665 | H30: =$M30*L$7 -> 8807.219 | I30: =$M30*M$7 -> 8807.219 | J30: =$M30*N$7 -> 4227.4651 | K30: =((G30+H30)+I30)+J30 -> 108334.57 | L30: ='Monthly Mortgage Calculation'!E109 -> 967864.03 | M30: =M29*(1+O$7) -> 1761443.8 | N30: =M30-L30 -> 793579.77 | P30: After 9 Years | Q30: =E30-N30 -> 2547.4415 | R30: =(-(E30-E$21-sum(D$21:D29))*($D$14))+E30-((M30-($H$17*M30))-L30) -> -58007.367
B31: =B30+1 -> 2033 | C31: =C30*(1+C$11) -> 72918.736 | D31: =K31-C31 -> 36252.518 | E31: =(E30)*(1+$D$12)+(1+$D$12/2)*D30 -> 898499.5 | G31: =IF((((B31-$B$21)+1)>$H$7),0,($K$13*12)) -> 86492.665 | H31: =$M31*L$8 -> 9071.4356 | I31: =$M31*M$8 -> 9071.4356 | J31: =$M31*N$8 -> 4535.7178 | K31: =((G31+H31)+I31)+J31 -> 109171.25 | L31: ='Monthly Mortgage Calculation'!E121 -> 926477.14 | M31: =M30*(1+O$7) -> 1814287.1 | N31: =M31-L31 -> 887809.97 | P31: After 10 Years | Q31: =E31-N31 -> 10689.533 | R31: =(-(E31-E$21-sum(D$21:D30))*($D$14))+E31-((M31-($H$17*M31))-L31) -> -71356.475
B32: =B31+1 -> 2034 | C32: =((C31*(1+C$12))) -> 74741.704 | D32: =K32-C32 -> 35109.907 | E32: =(E31)*(1+$D$12)+(1+$D$12/2)*D31 -> 1008082.1 | G32: =IF((((B32-$B$21)+1)>$H$7),0,($K$13*12)) -> 86492.665 | H32: =$M32*L$8 -> 9343.5786 | I32: =$M32*M$8 -> 9343.5786 | J32: =$M32*N$8 -> 4671.7893 | K32: =((G32+H32)+I32)+J32 -> 109851.61 | L32: ='Monthly Mortgage Calculation'!E133 -> 883079.85 | M32: =M31*(1+O$8) -> 1868715.7 | N32: =M32-L32 -> 985635.88 | P32: After 11 Years | Q32: =E32-N32 -> 22446.206 | R32: =(-(E32-E$21-sum(D$21:D31))*($D$14))+E32-((M32-($H$17*M32))-L32) -> -83904.608
B33: =B32+1 -> 2035 | C33: =C32*(1+C$12) -> 76610.247 | D33: =K33-C33 -> 33942.133 | E33: =(E32)*(1+$D$12)+(1+$D$12/2)*D32 -> 1125243 | G33: =IF((((B33-$B$21)+1)>$H$7),0,($K$13*12)) -> 86492.665 | H33: =$M33*L$8 -> 9623.886 | I33: =$M33*M$8 -> 9623.886 | J33: =$M33*N$8 -> 4811.943 | K33: =((G33+H33)+I33)+J33 -> 110552.38 | L33: ='Monthly Mortgage Calculation'!E145 -> 837574.49 | M33: =M32*(1+O$8) -> 1924777.2 | N33: =M33-L33 -> 1087202.7 | P33: After 12 Years | Q33: =E33-N33 -> 38040.244 | R33: =(-(E33-E$21-sum(D$21:D32))*($D$14))+E33-((M33-($H$17*M33))-L33) -> -95626.87
B34: =B33+1 -> 2036 | C34: =C33*(1+C$12) -> 78525.503 | D34: =K34-C34 -> 32748.668 | E34: =(E33)*(1+$D$12)+(1+$D$12/2)*D33 -> 1250562.2 | G34: =IF((((B34-$B$21)+1)>$H$7),0,($K$13*12)) -> 86492.665 | H34: =$M34*L$8 -> 9912.6026 | I34: =$M34*M$8 -> 9912.6026 | J34: =$M34*N$8 -> 4956.3013 | K34: =((G34+H34)+I34)+J34 -> 111274.17 | L34: ='Monthly Mortgage Calculation'!E157 -> 789858.66 | M34: =M33*(1+O$8) -> 1982520.5 | N34: =M34-L34 -> 1192661.9 | P34: After 13 Years | Q34: =E34-N34 -> 57900.355 | R34: =(-(E34-E$21-sum(D$21:D33))*($D$14))+E34-((M34-($H$17*M34))-L34) -> -106305.17
B35: =B34+1 -> 2037 | C35: =C34*(1+C$12) -> 80488.641 | D35: =K35-C35 -> 31528.976 | E35: =(E34)*(1+$D$12)+(1+$D$12/2)*D34 -> 1384665.8 | G35: =IF((((B35-$B$21)+1)>$H$7),0,($K$13*12)) -> 86492.665 | H35: =$M35*L$8 -> 10209.981 | I35: =$M35*M$8 -> 10209.981 | J35: =$M35*N$8 -> 5104.9903 | K35: =((G35+H35)+I35)+J35 -> 112017.62 | L35: ='Monthly Mortgage Calculation'!E169 -> 739824.99 | M35: =M34*(1+O$8) -> 2041996.1 | N35: =M35-L35 -> 1302171.1 | P35: After 14 Years | Q35: =E35-N35 -> 82494.659 | R35: =(-(E35-E$21-sum(D$21:D34))*($D$14))+E35-((M35-($H$17*M35))-L35) -> -115698.2
B36: =B35+1 -> 2038 | C36: =C35*(1+C$12) -> 82500.857 | D36: =K36-C36 -> 30282.508 | E36: =(E35)*(1+$D$12)+(1+$D$12/2)*D35 -> 1528229.2 | G36: =IF((((B36-$B$21)+1)>$H$7),0,($K$13*12)) -> 86492.665 | H36: =$M36*L$8 -> 10516.28 | I36: =$M36*M$8 -> 10516.28 | J36: =$M36*N$8 -> 5258.14 | K36: =((G36+H36)+I36)+J36 -> 112783.37 | L36: ='Monthly Mortgage Calculation'!E181 -> 687360.88 | M36: =M35*(1+O$8) -> 2103256 | N36: =M36-L36 -> 1415895.1 | P36: After 15 Years | Q36: =E36-N36 -> 112334.07 | R36: =(-(E36-E$21-sum(D$21:D35))*($D$14))+E36-((M36-($H$17*M36))-L36) -> -123539.34
B37: =B36+1 -> 2039 | C37: =C36*(1+C$12) -> 84563.378 | D37: =K37-C37 -> 29008.708 | E37: =(E36)*(1+$D$12)+(1+$D$12/2)*D36 -> 1681981.3 | G37: =IF((((B37-$B$21)+1)>$H$7),0,($K$13*12)) -> 86492.665 | H37: =$M37*L$8 -> 10831.768 | I37: =$M37*M$8 -> 10831.768 | J37: =$M37*N$8 -> 5415.8842 | K37: =((G37+H37)+I37)+J37 -> 113572.09 | L37: ='Monthly Mortgage Calculation'!E193 -> 632348.28 | M37: =M36*(1+O$8) -> 2166353.7 | N37: =M37-L37 -> 1534005.4 | P37: After 16 Years | Q37: =E37-N37 -> 147975.93 | R37: =(-(E37-E$21-sum(D$21:D36))*($D$14))+E37-((M37-($H$17*M37))-L37) -> -129534.41
B38: =B37+1 -> 2040 | C38: =C37*(1+C$12) -> 86677.463 | D38: =K38-C38 -> 27707.006 | E38: =(E37)*(1+$D$12)+(1+$D$12/2)*D37 -> 1846708.9 | G38: =IF((((B38-$B$21)+1)>$H$7),0,($K$13*12)) -> 86492.665 | H38: =$M38*L$8 -> 11156.722 | I38: =$M38*M$8 -> 11156.722 | J38: =$M38*N$8 -> 5578.3608 | K38: =((G38+H38)+I38)+J38 -> 114384.47 | L38: ='Monthly Mortgage Calculation'!E205 -> 574663.38 | M38: =M37*(1+O$8) -> 2231344.3 | N38: =M38-L38 -> 1656680.9 | P38: After 17 Years | Q38: =E38-N38 -> 190027.98 | R38: =(-(E38-E$21-sum(D$21:D37))*($D$14))+E38-((M38-($H$17*M38))-L38) -> -133359.19
B39: =B38+1 -> 2041 | C39: =C38*(1+C$12) -> 88844.399 | D39: =K39-C39 -> 26376.824 | E39: =(E38)*(1+$D$12)+(1+$D$12/2)*D38 -> 2023260.9 | G39: =IF((((B39-$B$21)+1)>$H$7),0,($K$13*12)) -> 86492.665 | H39: =$M39*L$8 -> 11491.423 | I39: =$M39*M$8 -> 11491.423 | J39: =$M39*N$8 -> 5745.7116 | K39: =((G39+H39)+I39)+J39 -> 115221.22 | L39: ='Monthly Mortgage Calculation'!E217 -> 514176.39 | M39: =M38*(1+O$8) -> 2298284.6 | N39: =M39-L39 -> 1784108.2 | P39: After 18 Years | Q39: =E39-N39 -> 239152.65 | R39: =(-(E39-E$21-sum(D$21:D38))*($D$14))+E39-((M39-($H$17*M39))-L39) -> -134656.76
B40: =B39+1 -> 2042 | C40: =C39*(1+C$12) -> 91065.509 | D40: =K40-C40 -> 25017.57 | E40: =(E39)*(1+$D$12)+(1+$D$12/2)*D39 -> 2212553.7 | G40: =IF((((B40-$B$21)+1)>$H$7),0,($K$13*12)) -> 86492.665 | H40: =$M40*L$8 -> 11836.166 | I40: =$M40*M$8 -> 11836.166 | J40: =$M40*N$8 -> 5918.0829 | K40: =((G40+H40)+I40)+J40 -> 116083.08 | L40: ='Monthly Mortgage Calculation'!E229 -> 450751.17 | M40: =M39*(1+O$8) -> 2367233.2 | N40: =M40-L40 -> 1916482 | P40: After 19 Years | Q40: =E40-N40 -> 296071.67 | R40: =(-(E40-E$21-sum(D$21:D39))*($D$14))+E40-((M40-($H$17*M40))-L40) -> -133034.61
B41: =B40+1 -> 2043 | C41: =C40*(1+C$12) -> 93342.147 | D41: =K41-C41 -> 23628.645 | E41: =(E40)*(1+$D$12)+(1+$D$12/2)*D40 -> 2415576.2 | G41: =IF((((B41-$B$21)+1)>$H$7),0,($K$13*12)) -> 86492.665 | H41: =$M41*L$8 -> 12191.251 | I41: =$M41*M$8 -> 12191.251 | J41: =$M41*N$8 -> 6095.6254 | K41: =((G41+H41)+I41)+J41 -> 116970.79 | L41: ='Monthly Mortgage Calculation'!E241 -> 384245.01 | M41: =M40*(1+O$8) -> 2438250.2 | N41: =M41-L41 -> 2054005.2 | P41: After 20 Years | Q41: =E41-N41 -> 361571.08 | R41: =(-(E41-E$21-sum(D$21:D40))*($D$14))+E41-((M41-($H$17*M41))-L41) -> -128061.52
...

Sheet Monthly  Mortgage Calculation
A1: Year | B1: Month | C1: Monthly Payment | D1: Monthly Interest | E1: Ending Principal | G1: Assumptions from previous page
A2: 2025 | B2: 1 | C2: =IF((((A2-$A$2)+1)>10),$I$15,IF((((A2-$A$2)+1)>5),$I$14,$I$13)) -> 6853.91 | D2: =IF((((A2-$A$2)+1)>10),$H$15,IF((((A2-$A$2)+1)>5),$H$14,$H$13))*H2 -> 4429.2475 | E2: =MAX((H2-(C2-D2)),0) -> 1274103 | G2: Mortgage Balance (opening) | H2: ='Assumptions and Summary'!H5*((1-'Assumptions and Summary'!H6)*(1+'Assumptions and Summary'!H13)) -> 1276527.7
A3: =IF((B3=1),(A2+1),A2) -> 2025 | B3: =IF((B2=12),1,(B2+1)) -> 2 | C3: =IF((((A3-$A$2)+1)>10),$I$15,IF((((A3-$A$2)+1)>5),$I$14,$I$13)) -> 6853.91 | D3: =IF((((A3-$A$2)+1)>10),$H$15,IF((((A3-$A$2)+1)>5),$H$14,$H$13))*E2 -> 4420.8345 | E3: =MAX((E2-(C3-D3)),0) -> 1271669.9 | G3: Amortization | H3: ='Assumptions and Summary'!H7 -> 25
A4: =IF((B4=1),(A3+1),A3) -> 2025 | B4: =IF((B3=12),1,(B3+1)) -> 3 | C4: =IF((((A4-$A$2)+1)>10),$I$15,IF((((A4-$A$2)+1)>5),$I$14,$I$13)) -> 6853.91 | D4: =IF((((A4-$A$2)+1)>10),$H$15,IF((((A4-$A$2)+1)>5),$H$14,$H$13))*E3 -> 4412.3923 | E4: =MAX((E3-(C4-D4)),0) -> 1269228.4
A5: =IF((B5=1),(A4+1),A4) -> 2025 | B5: =IF((B4=12),1,(B4+1)) -> 4 | C5: =IF((((A5-$A$2)+1)>10),$I$15,IF((((A5-$A$2)+1)>5),$I$14,$I$13)) -> 6853.91 | D5: =IF((((A5-$A$2)+1)>10),$H$15,IF((((A5-$A$2)+1)>5),$H$14,$H$13))*E4 -> 4403.9209 | E5: =MAX((E4-(C5-D5)),0) -> 1266778.4
A6: =IF((B6=1),(A5+1),A5) -> 2025 | B6: =IF((B5=12),1,(B5+1)) -> 5 | C6: =IF((((A6-$A$2)+1)>10),$I$15,IF((((A6-$A$2)+1)>5),$I$14,$I$13)) -> 6853.91 | D6: =IF((((A6-$A$2)+1)>10),$H$15,IF((((A6-$A$2)+1)>5),$H$14,$H$13))*E5 -> 4395.42 | E6: =MAX((E5-(C6-D6)),0) -> 1264319.9 | G6: Interest rates | H6: Stated rate
A7: =IF((B7=1),(A6+1),A6) -> 2025 | B7: =IF((B6=12),1,(B6+1)) -> 6 | C7: =IF((((A7-$A$2)+1)>10),$I$15,IF((((A7-$A$2)+1)>5),$I$14,$I$13)) -> 6853.91 | D7: =IF((((A7-$A$2)+1)>10),$H$15,IF((((A7-$A$2)+1)>5),$H$14,$H$13))*E6 -> 4386.8896 | E7: =MAX((E6-(C7-D7)),0) -> 1261852.9 | G7: ='Assumptions and Summary'!J6 -> First 5 Years | H7: ='Assumptions and Summary'!K6 -> 0.042
A8: =IF((B8=1),(A7+1),A7) -> 2025 | B8: =IF((B7=12),1,(B7+1)) -> 7 | C8: =IF((((A8-$A$2)+1)>10),$I$15,IF((((A8-$A$2)+1)>5),$I$14,$I$13)) -> 6853.91 | D8: =IF((((A8-$A$2)+1)>10),$H$15,IF((((A8-$A$2)+1)>5),$H$14,$H$13))*E7 -> 4378.3296 | E8: =MAX((E7-(C8-D8)),0) -> 1259377.3 | G8: ='Assumptions and Summary'!J7 -> Next 5 Years: | H8: ='Assumptions and Summary'!K7 -> 0.048
A9: =IF((B9=1),(A8+1),A8) -> 2025 | B9: =IF((B8=12),1,(B8+1)) -> 8 | C9: =IF((((A9-$A$2)+1)>10),$I$15,IF((((A9-$A$2)+1)>5),$I$14,$I$13)) -> 6853.91 | D9: =IF((((A9-$A$2)+1)>10),$H$15,IF((((A9-$A$2)+1)>5),$H$14,$H$13))*E8 -> 4369.7399 | E9: =MAX((E8-(C9-D9)),0) -> 1256893.2 | G9: ='Assumptions and Summary'!J8 -> Final 15 Years | H9: ='Assumptions and Summary'!K8 -> 0.048
A10: =IF((B10=1),(A9+1),A9) -> 2025 | B10: =IF((B9=12),1,(B9+1)) -> 9 | C10: =IF((((A10-$A$2)+1)>10),$I$15,IF((((A10-$A$2)+1)>5),$I$14,$I$13)) -> 6853.91 | D10: =IF((((A10-$A$2)+1)>10),$H$15,IF((((A10-$A$2)+1)>5),$H$14,$H$13))*E9 -> 4361.1205 | E10: =MAX((E9-(C10-D10)),0) -> 1254400.4
A11: =IF((B11=1),(A10+1),A10) -> 2025 | B11: =IF((B10=12),1,(B10+1)) -> 10 | C11: =IF((((A11-$A$2)+1)>10),$I$15,IF((((A11-$A$2)+1)>5),$I$14,$I$13)) -> 6853.91 | D11: =IF((((A11-$A$2)+1)>10),$H$15,IF((((A11-$A$2)+1)>5),$H$14,$H$13))*E10 -> 4352.4711 | E11: =MAX((E10-(C11-D11)),0) -> 1251898.9 | G11: Calculations
A12: =IF((B12=1),(A11+1),A11) -> 2025 | B12: =IF((B11=12),1,(B11+1)) -> 11 | C12: =IF((((A12-$A$2)+1)>10),$I$15,IF((((A12-$A$2)+1)>5),$I$14,$I$13)) -> 6853.91 | D12: =IF((((A12-$A$2)+1)>10),$H$15,IF((((A12-$A$2)+1)>5),$H$14,$H$13))*E11 -> 4343.7917 | E12: =MAX((E11-(C12-D12)),0) -> 1249388.8 | H12: monthly factor | I12: monthly payment
A13: =IF((B13=1),(A12+1),A12) -> 2025 | B13: =IF((B12=12),1,(B12+1)) -> 12 | C13: =IF((((A13-$A$2)+1)>10),$I$15,IF((((A13-$A$2)+1)>5),$I$14,$I$13)) -> 6853.91 | D13: =IF((((A13-$A$2)+1)>10),$H$15,IF((((A13-$A$2)+1)>5),$H$14,$H$13))*E12 -> 4335.0822 | E13: =MAX((E12-(C13-D13)),0) -> 1246870 | G13: ='Assumptions and Summary'!J11 -> First 5 Years | H13: =(((($H7/2)+1)^2)^(1/12)-1) -> 0.0034697623 | I13: =-PMT(H13,($H$3*12),H2) -> 6853.91
A14: =IF((B14=1),(A13+1),A13) -> 2026 | B14: =IF((B13=12),1,(B13+1)) -> 1 | C14: =IF((((A14-$A$2)+1)>10),$I$15,IF((((A14-$A$2)+1)>5),$I$14,$I$13)) -> 6853.91 | D14: =IF((((A14-$A$2)+1)>10),$H$15,IF((((A14-$A$2)+1)>5),$H$14,$H$13))*E13 -> 4326.3424 | E14: =MAX((E13-(C14-D14)),0) -> 1244342.4 | G14: ='Assumptions and Summary'!J12 -> Next 5 Years: | H14: =(((($H8/2)+1)^2)^(1/12)-1) -> 0.0039605769 | I14: =-PMT(H14,(($H$3-5)*12),$E$61) -> 7207.7221
A15: =IF((B15=1),(A14+1),A14) -> 2026 | B15: =IF((B14=12),1,(B14+1)) -> 2 | C15: =IF((((A15-$A$2)+1)>10),$I$15,IF((((A15-$A$2)+1)>5),$I$14,$I$13)) -> 6853.91 | D15: =IF((((A15-$A$2)+1)>10),$H$15,IF((((A15-$A$2)+1)>5),$H$14,$H$13))*E14 -> 4317.5724 | E15: =MAX((E14-(C15-D15)),0) -> 1241806.1 | G15: ='Assumptions and Summary'!J13 -> Final 15 Years | H15: =(((($H9/2)+1)^2)^(1/12)-1) -> 0.0039605769 | I15: =-PMT(H15,(($H$3-10)*12),$E$121) -> 7207.7221
A16: =IF((B16=1),(A15+1),A15) -> 2026 | B16: =IF((B15=12),1,(B15+1)) -> 3 | C16: =IF((((A16-$A$2)+1)>10),$I$15,IF((((A16-$A$2)+1)>5),$I$14,$I$13)) -> 6853.91 | D16: =IF((((A16-$A$2)+1)>10),$H$15,IF((((A16-$A$2)+1)>5),$H$14,$H$13))*E15 -> 4308.7719 | E16: =MAX((E15-(C16-D16)),0) -> 1239260.9
A17: =IF((B17=1),(A16+1),A16) -> 2026 | B17: =IF((B16=12),1,(B16+1)) -> 4 | C17: =IF((((A17-$A$2)+1)>10),$I$15,IF((((A17-$A$2)+1)>5),$I$14,$I$13)) -> 6853.91 | D17: =IF((((A17-$A$2)+1)>10),$H$15,IF((((A17-$A$2)+1)>5),$H$14,$H$13))*E16 -> 4299.9409 | E17: =MAX((E16-(C17-D17)),0) -> 1236707
A18: =IF((B18=1),(A17+1),A17) -> 2026 | B18: =IF((B17=12),1,(B17+1)) -> 5 | C18: =IF((((A18-$A$2)+1)>10),$I$15,IF((((A18-$A$2)+1)>5),$I$14,$I$13)) -> 6853.91 | D18: =IF((((A18-$A$2)+1)>10),$H$15,IF((((A18-$A$2)+1)>5),$H$14,$H$13))*E17 -> 4291.0792 | E18: =MAX((E17-(C18-D18)),0) -> 1234144.1
A19: =IF((B19=1),(A18+1),A18) -> 2026 | B19: =IF((B18=12),1,(B18+1)) -> 6 | C19: =IF((((A19-$A$2)+1)>10),$I$15,IF((((A19-$A$2)+1)>5),$I$14,$I$13)) -> 6853.91 | D19: =IF((((A19-$A$2)+1)>10),$H$15,IF((((A19-$A$2)+1)>5),$H$14,$H$13))*E18 -> 4282.1868 | E19: =MAX((E18-(C19-D19)),0) -> 1231572.4
A20: =IF((B20=1),(A19+1),A19) -> 2026 | B20: =IF((B19=12),1,(B19+1)) -> 7 | C20: =IF((((A20-$A$2)+1)>10),$I$15,IF((((A20-$A$2)+1)>5),$I$14,$I$13)) -> 6853.91 | D20: =IF((((A20-$A$2)+1)>10),$H$15,IF((((A20-$A$2)+1)>5),$H$14,$H$13))*E19 -> 4273.2635 | E20: =MAX((E19-(C20-D20)),0) -> 1228991.8
A21: =IF((B21=1),(A20+1),A20) -> 2026 | B21: =IF((B20=12),1,(B20+1)) -> 8 | C21: =IF((((A21-$A$2)+1)>10),$I$15,IF((((A21-$A$2)+1)>5),$I$14,$I$13)) -> 6853.91 | D21: =IF((((A21-$A$2)+1)>10),$H$15,IF((((A21-$A$2)+1)>5),$H$14,$H$13))*E20 -> 4264.3093 | E21: =MAX((E20-(C21-D21)),0) -> 1226402.2
A22: =IF((B22=1),(A21+1),A21) -> 2026 | B22: =IF((B21=12),1,(B21+1)) -> 9 | C22: =IF((((A22-$A$2)+1)>10),$I$15,IF((((A22-$A$2)+1)>5),$I$14,$I$13)) -> 6853.91 | D22: =IF((((A22-$A$2)+1)>10),$H$15,IF((((A22-$A$2)+1)>5),$H$14,$H$13))*E21 -> 4255.324 | E22: =MAX((E21-(C22-D22)),0) -> 1223803.6
A23: =IF((B23=1),(A22+1),A22) -> 2026 | B23: =IF((B22=12),1,(B22+1)) -> 10 | C23: =IF((((A23-$A$2)+1)>10),$I$15,IF((((A23-$A$2)+1)>5),$I$14,$I$13)) -> 6853.91 | D23: =IF((((A23-$A$2)+1)>10),$H$15,IF((((A23-$A$2)+1)>5),$H$14,$H$13))*E22 -> 4246.3075 | E23: =MAX((E22-(C23-D23)),0) -> 1221196
A24: =IF((B24=1),(A23+1),A23) -> 2026 | B24: =IF((B23=12),1,(B23+1)) -> 11 | C24: =IF((((A24-$A$2)+1)>10),$I$15,IF((((A24-$A$2)+1)>5),$I$14,$I$13)) -> 6853.91 | D24: =IF((((A24-$A$2)+1)>10),$H$15,IF((((A24-$A$2)+1)>5),$H$14,$H$13))*E23 -> 4237.2597 | E24: =MAX((E23-(C24-D24)),0) -> 1218579.3
A25: =IF((B25=1),(A24+1),A24) -> 2026 | B25: =IF((B24=12),1,(B24+1)) -> 12 | C25: =IF((((A25-$A$2)+1)>10),$I$15,IF((((A25-$A$2)+1)>5),$I$14,$I$13)) -> 6853.91 | D25: =IF((((A25-$A$2)+1)>10),$H$15,IF((((A25-$A$2)+1)>5),$H$14,$H$13))*E24 -> 4228.1806 | E25: =MAX((E24-(C25-D25)),0) -> 1215953.6
A26: =IF((B26=1),(A25+1),A25) -> 2027 | B26: =IF((B25=12),1,(B25+1)) -> 1 | C26: =IF((((A26-$A$2)+1)>10),$I$15,IF((((A26-$A$2)+1)>5),$I$14,$I$13)) -> 6853.91 | D26: =IF((((A26-$A$2)+1)>10),$H$15,IF((((A26-$A$2)+1)>5),$H$14,$H$13))*E25 -> 4219.0699 | E26: =MAX((E25-(C26-D26)),0) -> 1213318.8
A27: =IF((B27=1),(A26+1),A26) -> 2027 | B27: =IF((B26=12),1,(B26+1)) -> 2 | C27: =IF((((A27-$A$2)+1)>10),$I$15,IF((((A27-$A$2)+1)>5),$I$14,$I$13)) -> 6853.91 | D27: =IF((((A27-$A$2)+1)>10),$H$15,IF((((A27-$A$2)+1)>5),$H$14,$H$13))*E26 -> 4209.9277 | E27: =MAX((E26-(C27-D27)),0) -> 1210674.8
... A361: =IF((B361=1),(A360+1),A360) -> 2054 | B361: =IF((B360=12),1,(B360+1)) -> 12 | C361: =IF((((A361-$A$2)+1)>10),$I$15,IF((((A361-$A$2)+1)>5),$I$14,$I$13)) -> 7207.7221 | D361: =IF((((A361-$A$2)+1)>10),$H$15,IF((((A361-$A$2)+1)>5),$H$14,$H$13))*E360 -> 0 | E361: =MAX((E360-(C361-D361)),0) -> 0
